<?xml version="1.0" ?>
<!-- =================================================================================== -->
<!-- |    This document was autogenerated by xacro from bbot.xacro                     | -->
<!-- |    EDITING THIS FILE BY HAND IS NOT RECOMMENDED                                 | -->
<!-- =================================================================================== -->
<robot name="bbot" xmlns:xacro="http://www.ros.org/wiki/xacro">
  <link name="world"/>
  <link name="stage_base">
    <visual>
      <origin rpy="0 0 0" xyz="0 0 0"/>
      <geometry>
        <box size="1 1 0.1"/>
      </geometry>
    </visual>
  </link>
  <link name="stage_x_to_y"/>
  <link name="stage_y_to_passive"/>
  <link name="stage_passive">
    <visual>
      <origin rpy="0 0 0" xyz="0 0 0"/>
      <geometry>
        <box size="0.5 0.5 0.1"/>
      </geometry>
    </visual>
  </link>
  <link name="passive_x_to_y"/>
  <link name="passive_y_to_socket"/>
  <link name="socket_link">
    <visual>
      <origin rpy="0 0 0" xyz="0 0 0.25"/>
      <geometry>
        <cylinder length="0.5" radius="0.1"/>
      </geometry>
    </visual>
  </link>
  <link name="bs_link_1"/>
  <link name="bs_link_2"/>
  <link name="bs_link_3"/>
  <link name="bs_visual">
    <visual>
      <origin rpy="0 0 0" xyz="0 0 0"/>
      <geometry>
        <sphere radius="0.15"/>
      </geometry>
    </visual>
  </link>
  <link name="ee_link">
    <visual>
      <origin rpy="0 0 0" xyz="0 0 0"/>
      <geometry>
        <cylinder length="0.05" radius="0.05"/>
      </geometry>
    </visual>
  </link>
  <link name="ee_stage">
    <visual>
      <origin rpy="0 0 0" xyz="0 0 0"/>
      <geometry>
        <box size="0.5 0.5 0.05"/>
      </geometry>
    </visual>
  </link>
  <joint name="stage_base_z" type="prismatic">
    <parent link="world"/>
    <child link="stage_base"/>
    <origin rpy="0 0 0" xyz="0 0 0.05"/>
    <axis xyz="0 0 1"/>
    <limit effort="1.0" lower="-0.3" upper="0.3" velocity="1.0"/>
  </joint>
  <joint name="stage_base_x" type="prismatic">
    <parent link="stage_base"/>
    <child link="stage_x_to_y"/>
    <origin rpy="0 0 0" xyz="0 0 0"/>
    <axis xyz="1 0 0"/>
    <limit effort="1.0" lower="-0.3" upper="0.3" velocity="1.0"/>
  </joint>
  <joint name="stage_base_y" type="prismatic">
    <parent link="stage_x_to_y"/>
    <child link="stage_y_to_passive"/>
    <origin rpy="0 0 0" xyz="0 0 0"/>
    <axis xyz="0 1 0"/>
    <limit effort="1.0" lower="-0.3" upper="0.3" velocity="1.0"/>
  </joint>
  <joint name="passive_stage_z" type="prismatic">
    <parent link="stage_y_to_passive"/>
    <child link="stage_passive"/>
    <origin rpy="0 0 0" xyz="0 0 0.1"/>
    <axis xyz="0 0 1"/>
    <limit effort="1.0" lower="-0.2" upper="0.2" velocity="1.0"/>
  </joint>
  <joint name="passive_stage_x" type="prismatic">
    <parent link="stage_passive"/>
    <child link="passive_x_to_y"/>
    <origin rpy="0 0 0" xyz="0 0 0"/>
    <axis xyz="1 0 0"/>
    <limit effort="1.0" lower="-0.2" upper="0.2" velocity="1.0"/>
  </joint>
  <joint name="passive_stage_y" type="prismatic">
    <parent link="passive_x_to_y"/>
    <child link="passive_y_to_socket"/>
    <origin rpy="0 0 0" xyz="0 0 0"/>
    <axis xyz="0 1 0"/>
    <limit effort="1.0" lower="-0.2" upper="0.2" velocity="1.0"/>
  </joint>
  <joint name="base_to_socket" type="fixed">
    <parent link="passive_y_to_socket"/>
    <child link="socket_link"/>
    <origin rpy="0 0 0" xyz="0 0 0.05"/>
  </joint>
  <joint name="ball_socket_1" type="revolute">
    <parent link="socket_link"/>
    <child link="bs_link_1"/>
    <origin rpy="0 0 0" xyz="0 0 0.65"/>
    <axis xyz="1 0 0"/>
    <limit effort="1.0" lower="-1.57" upper="1.57" velocity="1.0"/>
  </joint>
  <joint name="ball_socket_2" type="revolute">
    <parent link="bs_link_1"/>
    <child link="bs_link_2"/>
    <origin rpy="0 0 0" xyz="0 0 0"/>
    <axis xyz="0 1 0"/>
    <limit effort="1.0" lower="-1.57" upper="1.57" velocity="1.0"/>
  </joint>
  <joint name="ball_socket_3" type="revolute">
    <parent link="bs_link_2"/>
    <child link="bs_link_3"/>
    <origin rpy="0 0 0" xyz="0 0 0"/>
    <axis xyz="0 0 1"/>
    <limit effort="1.0" lower="-1.57" upper="1.57" velocity="1.0"/>
  </joint>
  <joint name="ball_socket_4" type="fixed">
    <parent link="bs_link_3"/>
    <child link="bs_visual"/>
    <origin rpy="0 0 0" xyz="0 0 0"/>
  </joint>
  <joint name="ee_joint" type="fixed">
    <parent link="bs_visual"/>
    <child link="ee_link"/>
    <origin rpy="0 0 0" xyz="0 0 0.175"/>
  </joint>
  <joint name="end_joint" type="fixed">
    <parent link="ee_link"/>
    <child link="ee_stage"/>
    <origin rpy="0 0 0" xyz="0 0 0.05"/>
  </joint>
</robot>

